<sdf version='1.7'>
  <world name='default'>
    <light name='sun' type='directional'>
      <cast_shadows>1</cast_shadows>
      <pose>0 0 10 0 -0 0</pose>
      <diffuse>0.8 0.8 0.8 1</diffuse>
      <specular>0.2 0.2 0.2 1</specular>
      <attenuation>
        <range>1000</range>
        <constant>0.9</constant>
        <linear>0.01</linear>
        <quadratic>0.001</quadratic>
      </attenuation>
      <direction>-0.5 0.1 -0.9</direction>
      <spot>
        <inner_angle>0</inner_angle>
        <outer_angle>0</outer_angle>
        <falloff>0</falloff>
      </spot>
    </light>
    <model name='ground_plane'>
      <static>1</static>
      <link name='link'>
        <collision name='collision'>
          <geometry>
            <plane>
              <normal>0 0 1</normal>
              <size>100 100</size>
            </plane>
          </geometry>
          <surface>
            <friction>
              <ode>
                <mu>100</mu>
                <mu2>50</mu2>
              </ode>
              <torsional>
                <ode/>
              </torsional>
            </friction>
            <contact>
              <ode/>
            </contact>
            <bounce/>
          </surface>
          <max_contacts>10</max_contacts>
        </collision>
        <visual name='visual'>
          <cast_shadows>0</cast_shadows>
          <geometry>
            <plane>
              <normal>0 0 1</normal>
              <size>100 100</size>
            </plane>
          </geometry>
          <material>
            <script>
              <uri>file://media/materials/scripts/gazebo.material</uri>
              <name>Gazebo/Grey</name>
            </script>
          </material>
        </visual>
        <self_collide>0</self_collide>
        <enable_wind>0</enable_wind>
        <kinematic>0</kinematic>
      </link>
    </model>
    <gravity>0 0 -9.8</gravity>
    <magnetic_field>6e-06 2.3e-05 -4.2e-05</magnetic_field>
    <atmosphere type='adiabatic'/>
    <physics type='ode'>
      <max_step_size>0.001</max_step_size>
      <real_time_factor>1</real_time_factor>
      <real_time_update_rate>1000</real_time_update_rate>
    </physics>
    <scene>
      <ambient>0.4 0.4 0.4 1</ambient>
      <background>0.7 0.7 0.7 1</background>
      <shadows>1</shadows>
    </scene>
    <audio>
      <device>default</device>
    </audio>
    <wind/>
    <spherical_coordinates>
      <surface_model>EARTH_WGS84</surface_model>
      <latitude_deg>0</latitude_deg>
      <longitude_deg>0</longitude_deg>
      <elevation>0</elevation>
      <heading_deg>0</heading_deg>
    </spherical_coordinates>
    <model name='ARM'>
      <joint name='world_joint' type='fixed'>
        <pose relative_to='__model__'>0 0 0.7 0 -0 0</pose>
        <parent>world</parent>
        <child>base_link</child>
      </joint>
      <link name='base_link'>
        <pose relative_to='world_joint'>0 0 0 0 -0 0</pose>
        <inertial>
          <pose>-0.011731 -0.059961 -0.007003 0 -0 0</pose>
          <mass>1.81752</mass>
          <inertia>
            <ixx>0.0110265</ixx>
            <ixy>0.00232538</ixy>
            <ixz>-0.00816562</ixz>
            <iyy>0.0199903</iyy>
            <iyz>0.00238377</iyz>
            <izz>0.0106214</izz>
          </inertia>
        </inertial>
        <collision name='base_link_collision'>
          <pose>0 0 0 1.5708 -0 0</pose>
          <geometry>
            <mesh>
              <scale>0.001 0.001 0.001</scale>
              <uri>file:///home/ray/BUMRC_NewArm/src/install/arm_description/share/arm_description/meshes/base_link.stl</uri>
            </mesh>
          </geometry>
          <surface>
            <contact>
              <ode/>
            </contact>
            <friction>
              <ode>
                <mu>0.2</mu>
                <mu2>0.2</mu2>
              </ode>
              <torsional>
                <ode/>
              </torsional>
            </friction>
            <bounce/>
          </surface>
          <max_contacts>10</max_contacts>
        </collision>
        <collision name='base_link_collision_1'>
          <pose>0 0 -0.39 0 -0 0</pose>
          <geometry>
            <box>
              <size>0.2 0.2 0.61</size>
            </box>
          </geometry>
          <surface>
            <contact>
              <ode/>
            </contact>
            <friction>
              <ode>
                <mu>0.2</mu>
                <mu2>0.2</mu2>
              </ode>
              <torsional>
                <ode/>
              </torsional>
            </friction>
            <bounce/>
          </surface>
          <max_contacts>10</max_contacts>
        </collision>
        <collision name='base_link_fixed_joint_lump__camera_link_collision_2'>
          <pose>-0.2 -0.005 -0.2 -1.57159 1.17159 -3.14159</pose>
          <geometry>
            <box>
              <size>0.03 0.04 0.175</size>
            </box>
          </geometry>
          <surface>
            <contact>
              <ode/>
            </contact>
            <friction>
              <ode/>
              <torsional>
                <ode/>
              </torsional>
            </friction>
            <bounce/>
          </surface>
          <max_contacts>10</max_contacts>
        </collision>
        <visual name='base_link_visual'>
          <pose>0 0 0 1.5708 -0 0</pose>
          <geometry>
            <mesh>
              <scale>0.001 0.001 0.001</scale>
              <uri>file:///home/ray/BUMRC_NewArm/src/install/arm_description/share/arm_description/meshes/base_link.stl</uri>
            </mesh>
          </geometry>
          <material>
            <script>
              <name>Gazebo/Silver</name>
              <uri>file://media/materials/scripts/gazebo.material</uri>
            </script>
          </material>
        </visual>
        <visual name='base_link_visual_1'>
          <pose>0 0 -0.39 0 -0 0</pose>
          <geometry>
            <box>
              <size>0.2 0.2 0.61</size>
            </box>
          </geometry>
          <material>
            <script>
              <name>Gazebo/Silver</name>
              <uri>file://media/materials/scripts/gazebo.material</uri>
            </script>
          </material>
        </visual>
        <visual name='base_link_fixed_joint_lump__camera_link_visual_2'>
          <pose>-0.2 -0.005 -0.2 -1.57159 1.17159 -3.14159</pose>
          <geometry>
            <box>
              <size>0.03 0.04 0.175</size>
            </box>
          </geometry>
          <geometry>
            <mesh>
              <uri>__default__</uri>
            </mesh>
          </geometry>
          <material/>
        </visual>
        <self_collide>1</self_collide>
        <gravity>1</gravity>
        <sensor name='camera' type='depth'>
          <visualize>1</visualize>
          <update_rate>10</update_rate>
          <camera>
            <horizontal_fov>1.5708</horizontal_fov>
            <image>
              <format>R8G8B8</format>
              <width>1280</width>
              <height>720</height>
            </image>
            <clip>
              <near>0.03</near>
              <far>20</far>
            </clip>
          </camera>
          <plugin name='camera_controller' filename='libgazebo_ros_camera.so'>
            <frame_name>camera_optical_link</frame_name>
          </plugin>
          <pose>-0.2 -0.005 -0.2 -1.57159 1.17159 -3.14159</pose>
        </sensor>
        <enable_wind>0</enable_wind>
        <kinematic>0</kinematic>
      </link>
      <joint name='revolute_1' type='revolute'>
        <pose relative_to='base_link'>0.011548 -0.044828 0.01686 0 -0 0</pose>
        <parent>base_link</parent>
        <child>J1In_v1_1</child>
        <axis>
          <xyz>0 0 1</xyz>
          <limit>
            <lower>-1e+16</lower>
            <upper>1e+16</upper>
          </limit>
          <dynamics>
            <spring_reference>0</spring_reference>
            <spring_stiffness>0</spring_stiffness>
          </dynamics>
        </axis>
      </joint>
      <link name='J1In_v1_1'>
        <pose relative_to='revolute_1'>0 0 0 0 -0 0</pose>
        <inertial>
          <pose>-0.038305 0.019099 -0.0009 0 -0 0</pose>
          <mass>3.71925</mass>
          <inertia>
            <ixx>0.005026</ixx>
            <ixy>0.000275</ixy>
            <ixz>0.000273</ixz>
            <iyy>0.010497</iyy>
            <iyz>0.000102</iyz>
            <izz>0.006726</izz>
          </inertia>
        </inertial>
        <collision name='J1In_v1_1_collision'>
          <pose>-0.011548 0.044828 -0.01686 1.5708 -0 0</pose>
          <geometry>
            <mesh>
              <scale>0.001 0.001 0.001</scale>
              <uri>file:///home/ray/BUMRC_NewArm/src/install/arm_description/share/arm_description/meshes/J1In_v1_1.stl</uri>
            </mesh>
          </geometry>
          <surface>
            <contact>
              <ode/>
            </contact>
            <friction>
              <ode>
                <mu>0.2</mu>
                <mu2>0.2</mu2>
              </ode>
              <torsional>
                <ode/>
              </torsional>
            </friction>
            <bounce/>
          </surface>
          <max_contacts>10</max_contacts>
        </collision>
        <visual name='J1In_v1_1_visual'>
          <pose>-0.011548 0.044828 -0.01686 1.5708 -0 0</pose>
          <geometry>
            <mesh>
              <scale>0.001 0.001 0.001</scale>
              <uri>file:///home/ray/BUMRC_NewArm/src/install/arm_description/share/arm_description/meshes/J1In_v1_1.stl</uri>
            </mesh>
          </geometry>
          <material>
            <script>
              <name>Gazebo/Silver</name>
              <uri>file://media/materials/scripts/gazebo.material</uri>
            </script>
          </material>
        </visual>
        <self_collide>1</self_collide>
        <enable_wind>0</enable_wind>
        <kinematic>0</kinematic>
      </link>
      <joint name='revolute_8' type='revolute'>
        <pose relative_to='J1In_v1_1'>-0.136 0.02 -0.056 0 -0 0</pose>
        <parent>J1In_v1_1</parent>
        <child>Plate1_v1_1</child>
        <axis>
          <xyz>0 1 0</xyz>
          <limit>
            <lower>-1e+16</lower>
            <upper>1e+16</upper>
          </limit>
          <dynamics>
            <spring_reference>0</spring_reference>
            <spring_stiffness>0</spring_stiffness>
          </dynamics>
        </axis>
      </joint>
      <link name='Plate1_v1_1'>
        <pose relative_to='revolute_8'>0 0 0 0 -0 0</pose>
        <inertial>
          <pose>-0.216352 -0.017435 0.06115 0 -0 0</pose>
          <mass>4.81922</mass>
          <inertia>
            <ixx>0.005726</ixx>
            <ixy>-0.002855</ixy>
            <ixz>0.002383</ixz>
            <iyy>0.091947</iyy>
            <iyz>0.000429</iyz>
            <izz>0.089509</izz>
          </inertia>
        </inertial>
        <collision name='Plate1_v1_1_collision'>
          <pose>0.124452 0.024828 0.03914 1.5708 -0 0</pose>
          <geometry>
            <mesh>
              <scale>0.001 0.001 0.001</scale>
              <uri>file:///home/ray/BUMRC_NewArm/src/install/arm_description/share/arm_description/meshes/Plate1_v1_1.stl</uri>
            </mesh>
          </geometry>
          <surface>
            <contact>
              <ode/>
            </contact>
            <friction>
              <ode>
                <mu>0.2</mu>
                <mu2>0.2</mu2>
              </ode>
              <torsional>
                <ode/>
              </torsional>
            </friction>
            <bounce/>
          </surface>
          <max_contacts>10</max_contacts>
        </collision>
        <visual name='Plate1_v1_1_visual'>
          <pose>0.124452 0.024828 0.03914 1.5708 -0 0</pose>
          <geometry>
            <mesh>
              <scale>0.001 0.001 0.001</scale>
              <uri>file:///home/ray/BUMRC_NewArm/src/install/arm_description/share/arm_description/meshes/Plate1_v1_1.stl</uri>
            </mesh>
          </geometry>
          <material>
            <script>
              <name>Gazebo/Silver</name>
              <uri>file://media/materials/scripts/gazebo.material</uri>
            </script>
          </material>
        </visual>
        <self_collide>1</self_collide>
        <enable_wind>0</enable_wind>
        <kinematic>0</kinematic>
      </link>
      <joint name='revolute_9' type='revolute'>
        <pose relative_to='Plate1_v1_1'>-0.439478 -0.023031 0.0253 0 -0 0</pose>
        <parent>Plate1_v1_1</parent>
        <child>J2Out_v1_1</child>
        <axis>
          <xyz>0 1 0</xyz>
          <limit>
            <lower>-1e+16</lower>
            <upper>1e+16</upper>
          </limit>
          <dynamics>
            <spring_reference>0</spring_reference>
            <spring_stiffness>0</spring_stiffness>
          </dynamics>
        </axis>
      </joint>
      <link name='J2Out_v1_1'>
        <pose relative_to='revolute_9'>0 0 0 0 -0 0</pose>
        <inertial>
          <pose>-0.116508 -0.021776 0.035639 0 -0 0</pose>
          <mass>1.49759</mass>
          <inertia>
            <ixx>0.00122</ixx>
            <ixy>-0.000229</ixy>
            <ixz>-0.001081</ixz>
            <iyy>0.014253</iyy>
            <iyz>-6e-06</iyz>
            <izz>0.013542</izz>
          </inertia>
        </inertial>
        <collision name='J2Out_v1_1_collision'>
          <pose>0.56393 0.047859 0.01384 1.5708 -0 0</pose>
          <geometry>
            <mesh>
              <scale>0.001 0.001 0.001</scale>
              <uri>file:///home/ray/BUMRC_NewArm/src/install/arm_description/share/arm_description/meshes/J2Out_v1_1.stl</uri>
            </mesh>
          </geometry>
          <surface>
            <contact>
              <ode/>
            </contact>
            <friction>
              <ode>
                <mu>0.2</mu>
                <mu2>0.2</mu2>
              </ode>
              <torsional>
                <ode/>
              </torsional>
            </friction>
            <bounce/>
          </surface>
          <max_contacts>10</max_contacts>
        </collision>
        <visual name='J2Out_v1_1_visual'>
          <pose>0.56393 0.047859 0.01384 1.5708 -0 0</pose>
          <geometry>
            <mesh>
              <scale>0.001 0.001 0.001</scale>
              <uri>file:///home/ray/BUMRC_NewArm/src/install/arm_description/share/arm_description/meshes/J2Out_v1_1.stl</uri>
            </mesh>
          </geometry>
          <material>
            <script>
              <name>Gazebo/Silver</name>
              <uri>file://media/materials/scripts/gazebo.material</uri>
            </script>
          </material>
        </visual>
        <self_collide>1</self_collide>
        <enable_wind>0</enable_wind>
        <kinematic>0</kinematic>
      </link>
      <joint name='revolute_10' type='revolute'>
        <pose relative_to='J2Out_v1_1'>-0.384304 -0.023031 -0.0097 0 -0 0</pose>
        <parent>J2Out_v1_1</parent>
        <child>Small_Light_-_Spiral_Face_3.2M_20T_v1_1</child>
        <axis>
          <xyz>0 1 0</xyz>
          <limit>
            <lower>-1e+16</lower>
            <upper>1e+16</upper>
          </limit>
          <dynamics>
            <damping>5</damping>
            <friction>1</friction>
            <spring_reference>0</spring_reference>
            <spring_stiffness>0</spring_stiffness>
          </dynamics>
        </axis>
      </joint>
      <link name='Small_Light_-_Spiral_Face_3.2M_20T_v1_1'>
        <pose relative_to='revolute_10'>0 0 0 0 -0 0</pose>
        <inertial>
          <pose>-0.020047 5e-06 0.028257 0 -0 0</pose>
          <mass>0.821747</mass>
          <inertia>
            <ixx>0.000918</ixx>
            <ixy>0</ixy>
            <ixz>0.000298</ixz>
            <iyy>0.000962</iyy>
            <iyz>0</iyz>
            <izz>0.000753</izz>
          </inertia>
        </inertial>
        <collision name='Small_Light_-_Spiral_Face_3.2M_20T_v1_1_collision'>
          <pose>0.948234 0.07089 0.02354 1.5708 -0 0</pose>
          <geometry>
            <mesh>
              <scale>0.001 0.001 0.001</scale>
              <uri>file:///home/ray/BUMRC_NewArm/src/install/arm_description/share/arm_description/meshes/Small_Light_-_Spiral_Face_3.2M_20T_v1_1.stl</uri>
            </mesh>
          </geometry>
          <surface>
            <contact>
              <ode/>
            </contact>
            <friction>
              <ode>
                <mu>0.2</mu>
                <mu2>0.2</mu2>
              </ode>
              <torsional>
                <ode/>
              </torsional>
            </friction>
            <bounce/>
          </surface>
          <max_contacts>10</max_contacts>
        </collision>
        <visual name='Small_Light_-_Spiral_Face_3.2M_20T_v1_1_visual'>
          <pose>0.948234 0.07089 0.02354 1.5708 -0 0</pose>
          <geometry>
            <mesh>
              <scale>0.001 0.001 0.001</scale>
              <uri>file:///home/ray/BUMRC_NewArm/src/install/arm_description/share/arm_description/meshes/Small_Light_-_Spiral_Face_3.2M_20T_v1_1.stl</uri>
            </mesh>
          </geometry>
          <material>
            <script>
              <name>Gazebo/Silver</name>
              <uri>file://media/materials/scripts/gazebo.material</uri>
            </script>
          </material>
        </visual>
        <self_collide>1</self_collide>
        <enable_wind>0</enable_wind>
        <kinematic>0</kinematic>
      </link>
      <joint name='revolute_11' type='revolute'>
        <pose relative_to='Small_Light_-_Spiral_Face_3.2M_20T_v1_1'>-0.0424 0 0.0463 0 -0 0</pose>
        <parent>Small_Light_-_Spiral_Face_3.2M_20T_v1_1</parent>
        <child>Grabber_Base_v1_1</child>
        <axis>
          <xyz>1 0 0</xyz>
          <limit>
            <lower>-1e+16</lower>
            <upper>1e+16</upper>
          </limit>
          <dynamics>
            <spring_reference>0</spring_reference>
            <spring_stiffness>0</spring_stiffness>
          </dynamics>
        </axis>
      </joint>
      <link name='Grabber_Base_v1_1'>
        <pose relative_to='revolute_11'>0 0 0 0 -0 0</pose>
        <inertial>
          <pose>0.000651 2e-06 0.003321 0 -0 0</pose>
          <mass>0.984292</mass>
          <inertia>
            <ixx>0.00148</ixx>
            <ixy>0</ixy>
            <ixz>5.3e-05</ixz>
            <iyy>0.000585</iyy>
            <iyz>0</iyz>
            <izz>0.001318</izz>
          </inertia>
        </inertial>
        <collision name='Grabber_Base_v1_1_collision'>
          <pose>0.990634 0.07089 -0.02276 1.5708 -0 0</pose>
          <geometry>
            <mesh>
              <scale>0.001 0.001 0.001</scale>
              <uri>file:///home/ray/BUMRC_NewArm/src/install/arm_description/share/arm_description/meshes/Grabber_Base_v1_1.stl</uri>
            </mesh>
          </geometry>
          <surface>
            <contact>
              <ode/>
            </contact>
            <friction>
              <ode>
                <mu>0.2</mu>
                <mu2>0.2</mu2>
              </ode>
              <torsional>
                <ode/>
              </torsional>
            </friction>
            <bounce/>
          </surface>
          <max_contacts>10</max_contacts>
        </collision>
        <visual name='Grabber_Base_v1_1_visual'>
          <pose>0.990634 0.07089 -0.02276 1.5708 -0 0</pose>
          <geometry>
            <mesh>
              <scale>0.001 0.001 0.001</scale>
              <uri>file:///home/ray/BUMRC_NewArm/src/install/arm_description/share/arm_description/meshes/Grabber_Base_v1_1.stl</uri>
            </mesh>
          </geometry>
          <material>
            <script>
              <name>Gazebo/Silver</name>
              <uri>file://media/materials/scripts/gazebo.material</uri>
            </script>
          </material>
        </visual>
        <self_collide>1</self_collide>
        <enable_wind>0</enable_wind>
        <kinematic>0</kinematic>
      </link>
      <joint name='gripper_open_joint' type='prismatic'>
        <pose relative_to='Grabber_Base_v1_1'>0 0 0.003 0 -0 0</pose>
        <parent>Grabber_Base_v1_1</parent>
        <child>left_prong</child>
        <axis>
          <xyz>0 0 -1</xyz>
          <limit>
            <lower>0</lower>
            <upper>0.05</upper>
            <effort>5</effort>
            <velocity>1</velocity>
          </limit>
          <dynamics>
            <spring_reference>0</spring_reference>
            <spring_stiffness>0</spring_stiffness>
          </dynamics>
        </axis>
      </joint>
      <link name='left_prong'>
        <pose relative_to='gripper_open_joint'>0 0 0 0 -0 0</pose>
        <inertial>
          <pose>0 0 0 0 -0 0</pose>
          <mass>0.05</mass>
          <inertia>
            <ixx>1e-05</ixx>
            <ixy>0</ixy>
            <ixz>0</ixz>
            <iyy>1e-05</iyy>
            <iyz>0</iyz>
            <izz>1e-05</izz>
          </inertia>
        </inertial>
        <collision name='left_prong_collision'>
          <pose>-0.05 0.05 -0.035 0 -0 0</pose>
          <geometry>
            <box>
              <size>0.05 0.02 0.005</size>
            </box>
          </geometry>
          <max_contacts>10</max_contacts>
          <surface>
            <contact>
              <ode/>
            </contact>
            <bounce/>
            <friction>
              <torsional>
                <ode/>
              </torsional>
              <ode/>
            </friction>
          </surface>
        </collision>
        <visual name='left_prong_visual'>
          <pose>-0.05 0.05 -0.035 0 -0 0</pose>
          <geometry>
            <box>
              <size>0.05 0.02 0.005</size>
            </box>
          </geometry>
        </visual>
        <self_collide>0</self_collide>
        <enable_wind>0</enable_wind>
        <kinematic>0</kinematic>
      </link>
      <joint name='gripper_right_joint' type='prismatic'>
        <pose relative_to='Grabber_Base_v1_1'>0 0 0.03 0 -0 0</pose>
        <parent>Grabber_Base_v1_1</parent>
        <child>right_prong</child>
        <axis>
          <xyz>0 0 1</xyz>
          <limit>
            <lower>0</lower>
            <upper>0.05</upper>
            <effort>5</effort>
            <velocity>1</velocity>
          </limit>
          <dynamics>
            <spring_reference>0</spring_reference>
            <spring_stiffness>0</spring_stiffness>
          </dynamics>
        </axis>
      </joint>
      <link name='right_prong'>
        <pose relative_to='gripper_right_joint'>0 0 0 0 -0 0</pose>
        <inertial>
          <pose>0 0 0 0 -0 0</pose>
          <mass>0.05</mass>
          <inertia>
            <ixx>1e-05</ixx>
            <ixy>0</ixy>
            <ixz>0</ixz>
            <iyy>1e-05</iyy>
            <iyz>0</iyz>
            <izz>1e-05</izz>
          </inertia>
        </inertial>
        <collision name='right_prong_collision'>
          <pose>-0.05 0.05 -0.18 0 -0 0</pose>
          <geometry>
            <box>
              <size>0.05 0.02 0.005</size>
            </box>
          </geometry>
          <max_contacts>10</max_contacts>
          <surface>
            <contact>
              <ode/>
            </contact>
            <bounce/>
            <friction>
              <torsional>
                <ode/>
              </torsional>
              <ode/>
            </friction>
          </surface>
        </collision>
        <visual name='right_prong_visual'>
          <pose>-0.05 0.05 -0.18 0 -0 0</pose>
          <geometry>
            <box>
              <size>0.05 0.02 0.005</size>
            </box>
          </geometry>
        </visual>
        <self_collide>0</self_collide>
        <enable_wind>0</enable_wind>
        <kinematic>0</kinematic>
      </link>
      <static>0</static>
      <plugin name='gazebo_ros2_control' filename='libgazebo_ros2_control.so'>
        <parameters>/home/ray/BUMRC_NewArm/src/install/arm_description/share/arm_description/launch/controller.yaml</parameters>
      </plugin>
      <pose>0 0 0 0 -0 0</pose>
    </model>
    <model name='USB'>
      <link name='link_0'>
        <inertial>
          <mass>1</mass>
          <inertia>
            <ixx>0.166667</ixx>
            <ixy>0</ixy>
            <ixz>0</ixz>
            <iyy>0.166667</iyy>
            <iyz>0</iyz>
            <izz>0.166667</izz>
          </inertia>
          <pose>0 0 0 0 -0 0</pose>
        </inertial>
        <pose>0 -0 0 0 -0 0</pose>
        <gravity>1</gravity>
        <self_collide>0</self_collide>
        <kinematic>0</kinematic>
        <enable_wind>0</enable_wind>
        <visual name='visual'>
          <pose>0 0 0 0 -0 0</pose>
          <geometry>
            <box>
              <size>0.02 0.04 0.02</size>
            </box>
          </geometry>
          <material>
            <lighting>1</lighting>
            <script>
              <uri>file://media/materials/scripts/gazebo.material</uri>
              <name>Gazebo/Grey</name>
            </script>
            <shader type='pixel'>
              <normal_map>__default__</normal_map>
            </shader>
            <ambient>0.3 0.3 0.3 1</ambient>
            <diffuse>0.7 0.7 0.7 1</diffuse>
            <specular>0.01 0.01 0.01 1</specular>
            <emissive>0 0 0 1</emissive>
          </material>
          <transparency>0</transparency>
          <cast_shadows>1</cast_shadows>
        </visual>
        <collision name='collision'>
          <laser_retro>0</laser_retro>
          <max_contacts>10</max_contacts>
          <pose>0 0 0 0 -0 0</pose>
          <geometry>
            <box>
              <size>0.02 0.04 0.02</size>
            </box>
          </geometry>
          <surface>
            <friction>
              <ode>
                <mu>1</mu>
                <mu2>1</mu2>
                <fdir1>0 0 0</fdir1>
                <slip1>0</slip1>
                <slip2>0</slip2>
              </ode>
              <torsional>
                <coefficient>1</coefficient>
                <patch_radius>0</patch_radius>
                <surface_radius>0</surface_radius>
                <use_patch_radius>1</use_patch_radius>
                <ode>
                  <slip>0</slip>
                </ode>
              </torsional>
            </friction>
            <bounce>
              <restitution_coefficient>0</restitution_coefficient>
              <threshold>1e+06</threshold>
            </bounce>
            <contact>
              <collide_without_contact>0</collide_without_contact>
              <collide_without_contact_bitmask>1</collide_without_contact_bitmask>
              <collide_bitmask>1</collide_bitmask>
              <ode>
                <soft_cfm>0</soft_cfm>
                <soft_erp>0.2</soft_erp>
                <kp>1e+13</kp>
                <kd>1</kd>
                <max_vel>0.01</max_vel>
                <min_depth>0</min_depth>
              </ode>
              <bullet>
                <split_impulse>1</split_impulse>
                <split_impulse_penetration_threshold>-0.01</split_impulse_penetration_threshold>
                <soft_cfm>0</soft_cfm>
                <soft_erp>0.2</soft_erp>
                <kp>1e+13</kp>
                <kd>1</kd>
              </bullet>
            </contact>
          </surface>
        </collision>
      </link>
      <static>0</static>
      <allow_auto_disable>1</allow_auto_disable>
      <pose>-0.514879 0.131719 0 0 -0 0</pose>
    </model>
    <model name='bowl'>
      <link name='link'>
        <inertial>
          <pose>0 0 0.0175 0 -0 0</pose>
          <mass>0.1</mass>
          <inertia>
            <ixx>0.000250308</ixx>
            <ixy>0</ixy>
            <ixz>0</ixz>
            <iyy>0.000250308</iyy>
            <iyz>0</iyz>
            <izz>0.0004802</izz>
          </inertia>
        </inertial>
        <collision name='collision'>
          <pose>0 0 0.0175 0 -0 0</pose>
          <geometry>
            <cylinder>
              <radius>0.098</radius>
              <length>0.035</length>
            </cylinder>
          </geometry>
          <max_contacts>10</max_contacts>
          <surface>
            <contact>
              <ode/>
            </contact>
            <bounce/>
            <friction>
              <torsional>
                <ode/>
              </torsional>
              <ode/>
            </friction>
          </surface>
        </collision>
        <visual name='visual'>
          <geometry>
            <mesh>
              <uri>model://bowl/meshes/bowl.dae</uri>
            </mesh>
          </geometry>
        </visual>
        <self_collide>0</self_collide>
        <enable_wind>0</enable_wind>
        <kinematic>0</kinematic>
      </link>
      <pose>-0.481683 -0.045648 0 0 -0 0</pose>
    </model>
    <state world_name='default'>
      <sim_time>331 440000000</sim_time>
      <real_time>365 882273798</real_time>
      <wall_time>1771208850 180206734</wall_time>
      <iterations>331440</iterations>
      <model name='ARM'>
        <pose>-0 0 0 0 -0 0</pose>
        <scale>1 1 1</scale>
        <link name='Grabber_Base_v1_1'>
          <pose>-0.990439 -0.070879 0.694651 5e-06 0.019254 -1.1e-05</pose>
          <velocity>0.000598 1.8e-05 -0.009564 5.5e-05 0.006419 -1.9e-05</velocity>
          <acceleration>0.618923 0.017357 -9.56898 0.055386 0.135359 -0.018465</acceleration>
          <wrench>0.609201 0.017084 -9.41867 0 -0 0</wrench>
        </link>
        <link name='J1In_v1_1'>
          <pose>0.011548 -0.044828 0.71686 0 0 -1.1e-05</pose>
          <velocity>-0 -0 0 0 -0 -1.8e-05</velocity>
          <acceleration>0.000334 0.000671 0 3e-06 -0 -0.017524</acceleration>
          <wrench>0.001244 0.002496 2e-06 0 -0 0</wrench>
        </link>
        <link name='J2Out_v1_1'>
          <pose>-0.564518 -0.047853 0.64976 -0 0.019468 -1.1e-05</pose>
          <velocity>0.00031 1e-05 -0.012298 0 0.006419 -1.8e-05</velocity>
          <acceleration>0.552874 0.012118 -11.5551 0.001865 0.135961 -0.019481</acceleration>
          <wrench>0.827979 0.018148 -17.3048 0 -0 0</wrench>
        </link>
        <link name='Plate1_v1_1'>
          <pose>-0.124452 -0.024826 0.66086 -0 -0.082722 -1.1e-05</pose>
          <velocity>0 2e-06 0 0 -0.027947 -1.8e-05</velocity>
          <acceleration>-1.20355 0.006264 -6.16685 2.93532 -0.321289 3.03926</acceleration>
          <wrench>-5.80016 0.030186 -29.7194 0 -0 0</wrench>
        </link>
        <link name='Small_Light_-_Spiral_Face_3.2M_20T_v1_1'>
          <pose>-0.948938 -0.070879 0.647543 -0 0.019254 -1.1e-05</pose>
          <velocity>0.000295 1.7e-05 -0.009831 0 0.006419 -1.8e-05</velocity>
          <acceleration>0.479141 0.017169 -9.70561 8.6e-05 0.135357 -0.01777</acceleration>
          <wrench>0.393733 0.014109 -7.97556 0 -0 0</wrench>
        </link>
        <link name='base_link'>
          <pose>-0 -0 0.7 0 -0 0</pose>
          <velocity>0 0 -0 -0 -0 -0</velocity>
          <acceleration>-0 -0 0 0 -0 0</acceleration>
          <wrench>-0 -0 0 0 -0 0</wrench>
        </link>
        <link name='left_prong'>
          <pose>-0.990407 -0.070879 0.696299 5e-06 0.019254 -1.1e-05</pose>
          <velocity>0.000604 1.7e-05 -0.009812 5.5e-05 0.006419 -1.9e-05</velocity>
          <acceleration>0.603515 0.017462 -9.81162 -2e-06 0 0</acceleration>
          <wrench>0.030176 0.000873 -0.490581 0 -0 0</wrench>
        </link>
        <link name='right_prong'>
          <pose>-0.989861 -0.070879 0.724645 5e-06 0.019254 -1.1e-05</pose>
          <velocity>0.000785 1.6e-05 -0.009815 5.5e-05 0.006419 -1.9e-05</velocity>
          <acceleration>0.785456 0.01588 -9.81512 0 2e-06 0</acceleration>
          <wrench>0.039273 0.000794 -0.490756 0 -0 0</wrench>
        </link>
      </model>
      <model name='USB'>
        <pose>-0.514874 0.13172 0.010007 -9.6e-05 0.000508 -0</pose>
        <scale>1 1 1</scale>
        <link name='link_0'>
          <pose>-0.514874 0.13172 0.010007 -9.6e-05 0.000508 -0</pose>
          <velocity>0 0 0 0 -0 0</velocity>
          <acceleration>-0.005859 -0.011723 -0.029287 1.17173 -0.585593 0</acceleration>
          <wrench>-0.005859 -0.011723 -0.029287 0 -0 0</wrench>
        </link>
      </model>
      <model name='bowl'>
        <pose>-0.481683 -0.045648 -5e-06 5e-05 5e-05 0</pose>
        <scale>1 1 1</scale>
        <link name='link'>
          <pose>-0.481683 -0.045648 -5e-06 5e-05 5e-05 0</pose>
          <velocity>0 -0 -6.8e-05 0.098622 0.098622 0</velocity>
          <acceleration>3.26716 -3.26716 0.901969 1.29458 -1.29463 -3.14159</acceleration>
          <wrench>0.326716 -0.326716 0.090197 0 -0 0</wrench>
        </link>
      </model>
      <model name='ground_plane'>
        <pose>0 0 0 0 -0 0</pose>
        <scale>1 1 1</scale>
        <link name='link'>
          <pose>0 0 0 0 -0 0</pose>
          <velocity>0 0 0 0 -0 0</velocity>
          <acceleration>0 0 0 0 -0 0</acceleration>
          <wrench>0 0 0 0 -0 0</wrench>
        </link>
      </model>
      <light name='sun'>
        <pose>0 0 10 0 -0 0</pose>
      </light>
    </state>
    <gui fullscreen='0'>
      <camera name='user_camera'>
        <pose>0.893718 -1.19287 0.538919 0 0.275643 2.35619</pose>
        <view_controller>orbit</view_controller>
        <projection_type>perspective</projection_type>
      </camera>
    </gui>
  </world>
</sdf>
